sample_lob.txt
Date,Asset,bid3qty,bid3px,bid2qty,bid2px,bid1qty,bid1px,ask1px,ask1qty,ask2px,ask2qty,ask3px,ask3qty,Mold Package
2022-09-21 09:55:26.244327936,BANKA,10.0,11.78,51822.0,11.8,11110.0,11.81,0.0,0.0,0.0,0.0,0.0,0.0,A-B-11.81-6000-7621969089428617284;A-B-11.81-100-7621969089428723717;A-B-11.81-10-7621969089428724890;A-B-11.81-5000-7621969089428940862;A-B-11.8-1-7621969089428616329;A-B-11.8-10-7621969089428635705;A-B-11.8-10-7621969089428650454;A-B-11.8-100-7621969089428676159;A-B-11.8-580-7621969089428701336;A-B-11.8-50-7621969089428731879;A-B-11.8-31-7621969089428783141;A-B-11.8-1000-7621969089428840017;A-B-11.8-50000-7621969089428945087;A-B-11.8-40-7621969089428951475;A-B-11.78-10-7621969089428635715;A-B-11.77-6000-7621969089428617276;A-B-11.77-673-7621969089428752114;A-B-11.76-10-7621969089428635716
2022-09-21 09:55:26.244354816,BANKA,10.0,11.78,51822.0,11.8,11110.0,11.81,0.0,0.0,0.0,0.0,0.0,0.0,A-B-11.76-1000-7621969089428889683;A-B-11.75-500-7621969089428617097;A-B-11.75-50000-7621969089428671078;A-B-11.75-100-7621969089428752579;A-B-11.75-5000-7621969089428852290;A-B-11.75-450-7621969089428998873;A-B-11.74-6000-7621969089428617269;A-B-11.73-10-7621969089428635717;A-B-11.73-15000-7621969089428701887;A-B-11.72-1000-7621969089428618535;A-B-11.72-2573-7621969089428738321;A-B-11.72-3000-7621969089428834644;A-B-11.72-50-7621969089428954363;A-B-11.71-6000-7621969089428617260;A-B-11.71-199-7621969089428618653;A-B-11.71-10-7621969089428635719;A-B-11.7-200-7621969089428618089;A-B-11.7-50-7621969089428618828;A-B-11.7-10-7621969089428650407;A-B-11.7-20-7621969089428682485;A-B-11.7-700-7621969089428684833;A-B-11.7-6-7621969089428686667;A-B-11.7-100-7621969089428731867;A-B-11.7-2-7621969089428736401;A-B-11.7-200-7621969089428738872;A-B-11.7-2500-7621969089428932473;A-B-11.7-10000-7621969089428968666;A-B-11.69-10-7621969089428635720;A-B-11.69-200-7621969089428765513;A-B-11.68-6000-7621969089428617251;A-B-11.68-3-7621969089428736498;A-B-11.68-50000-7621969089428835748;A-B-11.68-15000-7621969089428986829;A-B-11.67-3059-7621969089428695492;A-B-11.67-137-7621969089428724576;A-B-11.65-6000-7621969089428617131;A-B-11.65-86-7621969089428679864
2022-09-21 09:55:26.244382464,BANKA,10.0,11.78,51822.0,11.8,11110.0,11.81,0.0,0.0,0.0,0.0,0.0,0.0,A-B-11.65-2-7621969089428687845;A-B-11.65-5000-7621969089428870688;A-B-11.64-5000-7621969089428651439;A-B-11.64-2000-7621969089428739231;A-B-11.63-4200-7621969089428751207;A-B-11.62-6000-7621969089428617119;A-B-11.62-700-7621969089428744617;A-B-11.62-3000-7621969089428785868;A-B-11.62-50000-7621969089428982945;A-B-11.61-86-7621969089428679849;A-B-11.61-500-7621969089428719072;A-B-11.61-100-7621969089428723718;A-B-11.61-5000-7621969089428940939;A-B-11.61-21-7621969089428657855;A-B-11.61-100-7621969089428996410;A-B-11.6-200-7621969089428618092;A-B-11.6-5-7621969089428647602;A-B-11.6-10-7621969089428650455;A-B-11.6-39-7621969089428683683;A-B-11.6-6-7621969089428692031;A-B-11.6-100-7621969089428695090;A-B-11.6-3944-7621969089428698606;A-B-11.6-300-7621969089428701389;A-B-11.6-500-7621969089428722405;A-B-11.6-200-7621969089428731876;A-B-11.6-1000-7621969089428744450;A-B-11.6-100-7621969089428741753;A-B-11.6-250-7621969089428938155;A-B-11.59-6000-7621969089428617107;A-B-11.58-1-7621969089428616955;A-B-11.58-1000-7621969089428682924;A-B-11.57-100-7621969089428679776;A-B-11.57-250-7621969089428731873;A-B-11.56-2-7621969089428722341;A-B-11.55-330-7621969089428617152;A-B-11.55-50-7621969089428618121;A-B-11.55-100-7621969089428627802
2022-09-21 09:55:26.244411648,BANKA,10.0,11.78,51822.0,11.8,11110.0,11.81,0.0,0.0,0.0,0.0,0.0,0.0,A-B-11.55-30-7621969089428656552;A-B-11.55-60-7621969089428667355;A-B-11.55-1100-7621969089428944280;A-B-11.54-100-7621969089428627796;A-B-11.54-2-7621969089428687847;A-B-11.54-17-7621969089428701442;A-B-11.54-40-7621969089428702132;A-B-11.53-100-7621969089428627793;A-B-11.53-850-7621969089428649419;A-B-11.53-2-7621969089428736013;A-B-11.52-15-7621969089428618133;A-B-11.52-100-7621969089428627786;A-B-11.52-30-7621969089428656553;A-B-11.52-1000-7621969089428690641;A-B-11.52-50-7621969089428957827;A-B-11.51-100-7621969089428627778;A-B-11.51-3000-7621969089428661396;A-B-11.51-1000-7621969089428666722;A-B-11.51-217-7621969089428676649;A-B-11.5-100-7621969089428617295;A-B-11.5-1000-7621969089428617791;A-B-11.5-75-7621969089428618721;A-B-11.5-75-7621969089428618723;A-B-11.5-1-7621969089428620404;A-B-11.5-10-7621969089428622914;A-B-11.5-100-7621969089428627774;A-B-11.5-200-7621969089428631438;A-B-11.5-7-7621969089428647636;A-B-11.5-10-7621969089428650453;A-B-11.5-100-7621969089428662445;A-B-11.5-168-7621969089428667960;A-B-11.5-100-7621969089428668742;A-B-11.5-15652-7621969089428674440;A-B-11.5-5-7621969089428678655;A-B-11.5-100-7621969089428679854;A-B-11.5-50-7621969089428680848;A-B-11.5-50-7621969089428682489
2022-09-21 09:55:26.244439808,BANKA,10.0,11.78,51822.0,11.8,11110.0,11.81,0.0,0.0,0.0,0.0,0.0,0.0,A-B-11.5-100-7621969089428683810;A-B-11.5-100-7621969089428695106;A-B-11.5-50-7621969089428700573;A-B-11.5-400-7621969089428722435;A-B-11.5-20-7621969089428723029;A-B-11.5-3367-7621969089428725947;A-B-11.5-1000-7621969089428729454;A-B-11.5-1000-7621969089428740177;A-B-11.5-20-7621969089428746958;A-B-11.5-269-7621969089428888943;A-B-11.5-20-7621969089428952685;A-B-11.49-100-7621969089428627765;A-B-11.49-30-7621969089428656557;A-B-11.49-21000-7621969089428775024;A-B-11.48-100-7621969089428627760;A-B-11.48-350-7621969089428739304;A-B-11.48-2-7621969089428962507;A-B-11.47-100-7621969089428627758;A-B-11.47-30-7621969089428656559;A-B-11.47-1-7621969089428735324;A-B-11.46-100-7621969089428627749;A-B-11.46-500-7621969089428686255;A-B-11.45-1000-7621969089428617803;A-B-11.45-10-7621969089428622921;A-B-11.45-100-7621969089428627747;A-B-11.45-10821-7621969089428696289;A-B-11.45-50-7621969089428700582;A-B-11.45-262-7621969089428735248;A-B-11.44-25-7621969089428626564;A-B-11.44-100-7621969089428627744;A-B-11.44-30-7621969089428656561;A-B-11.44-3-7621969089428687848;A-B-11.43-100-7621969089428622192;A-B-11.43-100-7621969089428627737;A-B-11.43-3-7621969089428736015;A-B-11.42-100-7621969089428627729;A-B-11.42-89-7621969089428654622
2022-09-21 09:55:26.244472576,BANKA,10.0,11.78,51822.0,11.8,11110.0,11.81,0.0,0.0,0.0,0.0,0.0,0.0,A-B-11.42-20-7621969089428656566;A-B-11.42-1000-7621969089428690642;A-B-11.42-100-7621969089428731535;A-B-11.42-10000-7621969089428776019;A-B-11.41-10-7621969089428620686;A-B-11.41-100-7621969089428627721;A-B-11.41-100-7621969089428723719;A-B-11.41-110-7621969089428986641;A-B-11.4-100-7621969089428617303;A-B-11.4-1000-7621969089428617940;A-B-11.4-10-7621969089428622924;A-B-11.4-100-7621969089428627718;A-B-11.4-1000-7621969089428637909;A-B-11.4-1500-7621969089428641421;A-B-11.4-10-7621969089428645748;A-B-11.4-8-7621969089428647678;A-B-11.4-1080-7621969089428648932;A-B-11.4-10-7621969089428650462;A-B-11.4-5-7621969089428665506;A-B-11.4-100-7621969089428671505;A-B-11.4-3000-7621969089428692882;A-B-11.4-1000-7621969089428693183;A-B-11.4-50-7621969089428700593;A-B-11.4-20-7621969089428705518;A-B-11.4-600-7621969089428722487;A-B-11.4-2-7621969089428727354;A-B-11.4-307-7621969089428731326;A-B-11.4-1-7621969089428749816;A-B-11.4-30-7621969089428849603;A-B-11.39-100-7621969089428627712;A-B-11.39-10-7621969089428643708;A-B-11.39-20-7621969089428656568;A-B-11.38-1000-7621969089428622419;A-B-11.38-100-7621969089428627568;A-B-11.38-3-7621969089428687857;A-B-11.38-1-7621969089428699945;A-B-11.38-10-7621969089428800919
2022-09-21 09:55:26.244515328,BANKA,10.0,11.78,51822.0,11.8,11110.0,11.81,0.0,0.0,0.0,0.0,0.0,0.0,A-B-11.37-100-7621969089428625532;A-B-11.36-6-7621969089428616475;A-B-11.36-100-7621969089428625527;A-B-11.36-20-7621969089428656570;A-B-11.36-500-7621969089428741675;A-B-11.36-4000-7621969089428799593;A-B-11.35-1000-7621969089428618376;A-B-11.35-10-7621969089428622927;A-B-11.35-100-7621969089428625522;A-B-11.35-100-7621969089428670556;A-B-11.35-50-7621969089428700628;A-B-11.35-41-7621969089428746342;A-B-11.34-100-7621969089428625520;A-B-11.34-30-7621969089428633164;A-B-11.34-100-7621969089428652440;A-B-11.34-20-7621969089428656575;A-B-11.34-1-7621969089428672863;A-B-11.33-100-7621969089428625511;A-B-11.33-5-7621969089428696693;A-B-11.33-3-7621969089428736017;A-B-11.32-1000-7621969089428617188;A-B-11.32-100-7621969089428625500;A-B-11.32-43-7621969089428642105;A-B-11.32-1000-7621969089428690645;A-B-11.31-100-7621969089428625490;A-B-11.31-20-7621969089428656581;A-B-11.31-300-7621969089428738181;A-B-11.3-200-7621969089428617130;A-B-11.3-100-7621969089428617312;A-B-11.3-1000-7621969089428618637;A-B-11.3-100-7621969089428622365;A-B-11.3-100-7621969089428625486;A-B-11.3-10-7621969089428627696;A-B-11.3-300-7621969089428631448;A-B-11.3-35-7621969089428633085;A-B-11.3-9-7621969089428647712;A-B-11.3-10-7621969089428650456
